<?xml version="1.0" encoding="utf-8"?>
<!-- =================================================================================== -->
<!-- |    This document was autogenerated by xacro from ur5_onrobot.urdf.xacro         | -->
<!-- |    EDITING THIS FILE BY HAND IS NOT RECOMMENDED                                 | -->
<!-- =================================================================================== -->
<robot name="rilab_robot">
  <!--property name="shoulder_height" value="0.089159" /-->
  <!--property name="shoulder_offset" value="0.13585" /-->
  <!-- shoulder_offset - elbow_offset + wrist_1_length = 0.10915 -->
  <!--property name="upper_arm_length" value="0.42500" /-->
  <!--property name="elbow_offset" value="0.1197" /-->
  <!-- CAD measured -->
  <!--property name="forearm_length" value="0.39225" /-->
  <!--property name="wrist_1_length" value="0.093" /-->
  <!-- CAD measured -->
  <!--property name="wrist_2_length" value="0.09465" /-->
  <!-- In CAD this distance is 0.930, but in the spec it is 0.09465 -->
  <!--property name="wrist_3_length" value="0.0823" /-->
  <!-- manually measured -->
  <link name="base_link">
    <visual>
      <geometry>
        <mesh filename="package://ir_gazebo/urdf/ur5e/meshes/visual/base.dae"/>
      </geometry>
      <material name="LightGrey">
        <color rgba="0.7 0.7 0.7 1.0"/>
      </material>
    </visual>
    <collision>
      <geometry>
        <mesh filename="package://ir_gazebo/urdf/ur5e/meshes/collision/base.stl"/>
      </geometry>
    </collision>
    <inertial>
      <mass value="4.0"/>
      <origin rpy="0 0 0" xyz="0.0 0.0 0.0"/>
      <inertia ixx="0.00443333156" ixy="0.0" ixz="0.0" iyy="0.00443333156" iyz="0.0" izz="0.0072"/>
    </inertial>
  </link>
  <joint name="shoulder_pan_joint" type="revolute">
    <parent link="base_link"/>
    <child link="shoulder_link"/>
    <origin rpy="0.0 0.0 0.0" xyz="0.0 0.0 0.163"/>
    <axis xyz="0 0 1"/>
    <limit effort="150.0" lower="-3.14159265359" upper="3.14159265359" velocity="3.14"/>
    <dynamics damping="0.0" friction="0.0"/>
  </joint>
  <link name="shoulder_link">
    <visual>
      <geometry>
        <mesh filename="package://ir_gazebo/urdf/ur5e/meshes/visual/shoulder.dae"/>
      </geometry>
      <material name="LightGrey">
        <color rgba="0.7 0.7 0.7 1.0"/>
      </material>
    </visual>
    <collision>
      <geometry>
        <mesh filename="package://ir_gazebo/urdf/ur5e/meshes/collision/shoulder.stl"/>
      </geometry>
    </collision>
    <inertial>
      <mass value="3.7"/>
      <origin rpy="0 0 0" xyz="0.0 0.0 0.0"/>
      <inertia ixx="0.010267495893" ixy="0.0" ixz="0.0" iyy="0.010267495893" iyz="0.0" izz="0.00666"/>
    </inertial>
  </link>
  <joint name="shoulder_lift_joint" type="revolute">
    <parent link="shoulder_link"/>
    <child link="upper_arm_link"/>
    <origin rpy="0.0 1.57079632679 0.0" xyz="0.0 0.138 0.0"/>
    <!--origin: rpy="0.0 ${pi / 2.0} 0.0"-->
    <axis xyz="0 1 0"/>
    <limit effort="150.0" lower="-3.14159265359" upper="3.14159265359" velocity="3.14"/>
    <dynamics damping="0.0" friction="0.0"/>
  </joint>
  <link name="upper_arm_link">
    <visual>
      <geometry>
        <mesh filename="package://ir_gazebo/urdf/ur5e/meshes/visual/upperarm.dae"/>
      </geometry>
      <material name="LightGrey">
        <color rgba="0.7 0.7 0.7 1.0"/>
      </material>
    </visual>
    <collision>
      <geometry>
        <mesh filename="package://ir_gazebo/urdf/ur5e/meshes/collision/upperarm.stl"/>
      </geometry>
    </collision>
    <inertial>
      <mass value="8.393"/>
      <origin rpy="0 0 0" xyz="0.0 0.0 0.2125"/>
      <inertia ixx="0.133885781862" ixy="0.0" ixz="0.0" iyy="0.133885781862" iyz="0.0" izz="0.0151074"/>
    </inertial>
  </link>
  <joint name="elbow_joint" type="revolute">
    <parent link="upper_arm_link"/>
    <child link="forearm_link"/>
    <origin rpy="0.0 0.0 0.0" xyz="0.0 -0.131 0.425"/>
    <axis xyz="0 1 0"/>
    <limit effort="150.0" lower="-3.14159265359" upper="3.14159265359" velocity="3.14"/>
    <dynamics damping="0.0" friction="0.0"/>
  </joint>
  <link name="forearm_link">
    <visual>
      <geometry>
        <mesh filename="package://ir_gazebo/urdf/ur5e/meshes/visual/forearm.dae"/>
      </geometry>
      <material name="LightGrey">
        <color rgba="0.7 0.7 0.7 1.0"/>
      </material>
    </visual>
    <collision>
      <geometry>
        <mesh filename="package://ir_gazebo/urdf/ur5e/meshes/collision/forearm.stl"/>
      </geometry>
    </collision>
    <inertial>
      <mass value="2.275"/>
      <origin rpy="0 0 0" xyz="0.0 0.0 0.196"/>
      <inertia ixx="0.0311796208615" ixy="0.0" ixz="0.0" iyy="0.0311796208615" iyz="0.0" izz="0.004095"/>
    </inertial>
  </link>
  <joint name="wrist_1_joint" type="revolute">
    <parent link="forearm_link"/>
    <child link="wrist_1_link"/>
    <origin rpy="0.0 1.57079632679 0.0" xyz="0.0 0.0 0.392"/>
    <!-- origin: rpy="0.0 ${pi / 2.0} 0.0"-->
    <axis xyz="0 1 0"/>
    <limit effort="28.0" lower="-3.14159265359" upper="3.14159265359" velocity="6.28"/>
    <dynamics damping="0.0" friction="0.0"/>
  </joint>
  <link name="wrist_1_link">
    <visual>
      <geometry>
        <mesh filename="package://ir_gazebo/urdf/ur5e/meshes/visual/wrist1.dae"/>
      </geometry>
      <material name="LightGrey">
        <color rgba="0.7 0.7 0.7 1.0"/>
      </material>
    </visual>
    <collision>
      <geometry>
        <mesh filename="package://ir_gazebo/urdf/ur5e/meshes/collision/wrist1.stl"/>
      </geometry>
    </collision>
    <inertial>
      <mass value="1.219"/>
      <origin rpy="0 0 0" xyz="0.0 0.127 0.0"/>
      <inertia ixx="0.00255989897604" ixy="0.0" ixz="0.0" iyy="0.00255989897604" iyz="0.0" izz="0.0021942"/>
    </inertial>
  </link>
  <joint name="wrist_2_joint" type="revolute">
    <parent link="wrist_1_link"/>
    <child link="wrist_2_link"/>
    <origin rpy="0.0 0.0 0.0" xyz="0.0 0.127 0.0"/>
    <axis xyz="0 0 1"/>
    <limit effort="28.0" lower="-3.14159265359" upper="3.14159265359" velocity="6.28"/>
    <dynamics damping="0.0" friction="0.0"/>
  </joint>
  <link name="wrist_2_link">
    <visual>
      <geometry>
        <mesh filename="package://ir_gazebo/urdf/ur5e/meshes/visual/wrist2.dae"/>
      </geometry>
      <material name="LightGrey">
        <color rgba="0.7 0.7 0.7 1.0"/>
      </material>
    </visual>
    <collision>
      <geometry>
        <mesh filename="package://ir_gazebo/urdf/ur5e/meshes/collision/wrist2.stl"/>
      </geometry>
    </collision>
    <inertial>
      <mass value="1.219"/>
      <origin rpy="0 0 0" xyz="0.0 0.0 0.1"/>
      <inertia ixx="0.00255989897604" ixy="0.0" ixz="0.0" iyy="0.00255989897604" iyz="0.0" izz="0.0021942"/>
    </inertial>
  </link>
  <joint name="wrist_3_joint" type="revolute">
    <parent link="wrist_2_link"/>
    <child link="wrist_3_link"/>
    <origin rpy="0.0 0.0 0.0" xyz="0.0 0.0 0.1"/>
    <axis xyz="0 1 0"/>
    <limit effort="28.0" lower="-3.14159265359" upper="3.14159265359" velocity="6.28"/>
    <dynamics damping="0.0" friction="0.0"/>
  </joint>
  <link name="wrist_3_link">
    <visual>
      <geometry>
        <mesh filename="package://ir_gazebo/urdf/ur5e/meshes/visual/wrist3.dae"/>
      </geometry>
      <material name="LightGrey">
        <color rgba="0.7 0.7 0.7 1.0"/>
      </material>
    </visual>
    <collision>
      <geometry>
        <mesh filename="package://ir_gazebo/urdf/ur5e/meshes/collision/wrist3.stl"/>
      </geometry>
    </collision>
    <inertial>
      <mass value="0.1879"/>
      <origin rpy="1.57079632679 0 0" xyz="0.0 0.0771 0.0"/>
      <inertia ixx="9.89041005217e-05" ixy="0.0" ixz="0.0" iyy="9.89041005217e-05" iyz="0.0" izz="0.0001321171875"/>
    </inertial>
  </link>
  <joint name="ee_fixed_joint" type="fixed">
    <parent link="wrist_3_link"/>
    <child link="tool0"/>
    <origin rpy="0 0 0" xyz="0.0 0.1 0.0"/>   <!-- <before rpy="-1.57 0 0" xyz="0.0 0.1 0.0"/> -->
    <axis xyz="0 1 0"/>
  </joint>
  <link name="tool0">
    <collision>
      <geometry>
        <box size="0.01 0.01 0.01"/>
      </geometry>
      <origin rpy="0 0 0" xyz="-0.01 0 0"/>
    </collision>
  </link>
  <joint name="gripper_base_joint" type="fixed">
    <parent link="tool0"/>
    <child link="gripper_base_link"/>
    <origin rpy="-1.57 0 0" xyz="0 0 0"/>   <!--<origin rpy="0 0 0" xyz="0 0 0"/> -->
    <axis xyz="0 1 0"/>
  </joint>
  <link name="gripper_base_link">
    <inertial>
      <origin rpy="0 0 0" xyz="-0.000118835633453291 4.70054905894546E-06 0.0572680906518555"/>
      <mass value="0.199035856566616"/>
      <inertia ixx="0.000170600248402307" ixy="3.75673847481297E-08" ixz="4.71579777629836E-08" iyy="0.000213152093040191" iyz="-1.76513863534777E-07" izz="5.59878626220752E-05"/>
    </inertial>
    <visual>
      <origin rpy="0 0 0" xyz="0 0 0"/>
      <geometry>
        <mesh filename="package://ir_gazebo/urdf/rg2/meshes/visual/gripper_base_link.dae"/>
      </geometry>
      <material name="White">
        <color rgba="1 1 1 1"/>
      </material>
    </visual>
    <collision>
      <origin rpy="0 0 0" xyz="0 0 0"/>
      <geometry>
        <mesh filename="package://ir_gazebo/urdf/rg2/meshes/collision/gripper_base_link.STL"/>
      </geometry>
    </collision>
  </link>
  <link name="gripper_finger1_finger_link">
    <inertial>
      <origin rpy="0 0 0" xyz="0.0010718088996676 0.0103000002725817 0.00719447424225184"/>
      <mass value="0.0157597232324457"/>
      <inertia ixx="4.77930907548385E-06" ixy="-3.38189802725612E-15" ixz="-1.64279014982784E-07" iyy="4.865441590744E-06" iyz="-1.3392990014795E-14" izz="1.31307089078094E-06"/>
    </inertial>
    <visual>
      <origin rpy="0 0 0" xyz="0 0 0"/>
      <geometry>
        <mesh filename="package://ir_gazebo/urdf/rg2/meshes/visual/gripper_finger1_finger_link.dae"/>
      </geometry>
      <material name="White">
        <color rgba="1 1 1 1"/>
      </material>
    </visual>
    <collision>
      <origin rpy="0 0 0" xyz="0 0 0"/>
      <geometry>
        <mesh filename="package://ir_gazebo/urdf/rg2/meshes/collision/gripper_finger1_finger_link.STL"/>
      </geometry>
    </collision>
  </link>
  <joint name="gripper_finger1_joint" type="revolute">
    <origin rpy="0 0 0" xyz="0.0169 -0.0103 0.105"/>
    <parent link="gripper_base_link"/>
    <child link="gripper_finger1_finger_link"/>
    <axis xyz="0 1 0"/>
    <limit effort="1000" lower="0" upper="0.8" velocity="2"/>
  </joint>
  <link name="gripper_finger1_inner_knuckle_link">
    <inertial>
      <origin rpy="0 0 0" xyz="0.000752725541911719 0.00999999924320924 0.0203934641019564"/>
      <mass value="0.00491742236496327"/>
      <inertia ixx="1.98120134788244E-06" ixy="-6.4357476071842E-14" ixz="-6.20941625040096E-08" iyy="1.77599017859716E-06" iyz="-1.09055934131207E-14" izz="2.48948112270257E-07"/>
    </inertial>
    <visual>
      <origin rpy="0 0 0" xyz="0 0 0"/>
      <geometry>
        <mesh filename="package://ir_gazebo/urdf/rg2/meshes/visual/gripper_finger1_inner_knuckle_link.dae"/>
      </geometry>
      <material name="White">
        <color rgba="1 1 1 1"/>
      </material>
    </visual>
    <collision>
      <origin rpy="0 0 0" xyz="0 0 0"/>
      <geometry>
        <mesh filename="package://ir_gazebo/urdf/rg2/meshes/collision/gripper_finger1_inner_knuckle_link.STL"/>
      </geometry>
    </collision>
  </link>
  <joint name="gripper_finger1_inner_knuckle_joint" type="continuous">
    <origin rpy="0 0 0" xyz="0.0074 -0.01 0.1215"/>
    <parent link="gripper_base_link"/>
    <child link="gripper_finger1_inner_knuckle_link"/>
    <axis xyz="0 1 0"/>
    <limit effort="0.1" lower="-3.14" upper="3.14" velocity="100"/>
    <mimic joint="gripper_finger1_joint" offset="0"/>
  </joint>
  <link name="gripper_finger1_finger_tip_link">
    <inertial>
      <origin rpy="0 0 0" xyz="-0.0011594416667826 0.00580000072518588 0.0107764194581964"/>
      <mass value="0.00872849065417813"/>
      <inertia ixx="1.50886455139492E-06" ixy="-1.78552626714452E-14" ixz="2.60234059895028E-07" iyy="1.45214737233688E-06" iyz="9.35094538565976E-14" izz="3.57695503495602E-07"/>
    </inertial>
    <visual>
      <origin rpy="0 0 0" xyz="0 0 0"/>
      <geometry>
        <mesh filename="package://ir_gazebo/urdf/rg2/meshes/visual/gripper_finger1_finger_tip_link.dae"/>
      </geometry>
      <material name="White">
        <color rgba="1 1 1 1"/>
      </material>
    </visual>
    <collision>
      <origin rpy="0 0 0" xyz="0 0 0"/>
      <geometry>
        <mesh filename="package://ir_gazebo/urdf/rg2/meshes/collision/gripper_finger1_finger_tip_link.STL"/>
      </geometry>
    </collision>
  </link>
  <joint name="gripper_finger1_finger_tip_joint" type="continuous">
    <origin rpy="0 0 0" xyz="0.002 0.0042 0.054964"/>
    <parent link="gripper_finger1_inner_knuckle_link"/>
    <child link="gripper_finger1_finger_tip_link"/>
    <axis xyz="0 1 0"/>
    <limit effort="0.1" lower="-3.14" upper="3.14" velocity="100"/>
    <mimic joint="gripper_finger1_joint" multiplier="-1"/>
  </joint>
  <link name="gripper_finger2_finger_link">
    <inertial>
      <origin rpy="0 0 0" xyz="-0.00107180889966652 0.0102999997274183 0.00719447424225199"/>
      <mass value="0.0157597232324457"/>
      <inertia ixx="4.7793090754839E-06" ixy="-3.38189802615458E-15" ixz="1.64279014982266E-07" iyy="4.865441590744E-06" iyz="1.33929898462312E-14" izz="1.31307089078089E-06"/>
    </inertial>
    <visual>
      <origin rpy="0 0 0" xyz="0 0 0"/>
      <geometry>
        <mesh filename="package://ir_gazebo/urdf/rg2/meshes/visual/gripper_finger2_finger_link.dae"/>
      </geometry>
      <material name="White">
        <color rgba="1 1 1 1"/>
      </material>
    </visual>
    <collision>
      <origin rpy="0 0 0" xyz="0 0 0"/>
      <geometry>
        <mesh filename="package://ir_gazebo/urdf/rg2/meshes/collision/gripper_finger2_finger_link.STL"/>
      </geometry>
    </collision>
  </link>
  <joint name="gripper_finger2_joint" type="revolute">
    <origin rpy="0 0 0" xyz="-0.0171 -0.0103 0.105"/>
    <parent link="gripper_base_link"/>
    <child link="gripper_finger2_finger_link"/>
    <axis xyz="0 1 0"/>
    <limit effort="1000" lower="-3.14" upper="3.14" velocity="100"/>
    <mimic joint="gripper_finger1_joint" multiplier="-1"/>
  </joint>
  <link name="gripper_finger2_inner_knuckle_link">
    <inertial>
      <origin rpy="0 0 0" xyz="-0.000752725541908486 0.0100000007567908 0.0203934641019566"/>
      <mass value="0.00491742236496327"/>
      <inertia ixx="1.98120134788246E-06" ixy="-6.43574760392122E-14" ixz="6.20941625037353E-08" iyy="1.77599017859716E-06" iyz="1.09055934323118E-14" izz="2.48948112270238E-07"/>
    </inertial>
    <visual>
      <origin rpy="0 0 0" xyz="0 0 0"/>
      <geometry>
        <mesh filename="package://ir_gazebo/urdf/rg2/meshes/visual/gripper_finger2_inner_knuckle_link.dae"/>
      </geometry>
      <material name="White">
        <color rgba="1 1 1 1"/>
      </material>
    </visual>
    <collision>
      <origin rpy="0 0 0" xyz="0 0 0"/>
      <geometry>
        <mesh filename="package://ir_gazebo/urdf/rg2/meshes/collision/gripper_finger2_inner_knuckle_link.STL"/>
      </geometry>
    </collision>
  </link>
  <joint name="gripper_finger2_inner_knuckle_joint" type="continuous">
    <origin rpy="0 0 0" xyz="-0.0076 -0.01 0.1215"/>
    <parent link="gripper_base_link"/>
    <child link="gripper_finger2_inner_knuckle_link"/>
    <axis xyz="0 1 0"/>
    <limit effort="0.1" lower="-3.14" upper="3.14" velocity="100"/>
    <mimic joint="gripper_finger1_joint" multiplier="-1"/>
  </joint>
  <link name="gripper_finger2_finger_tip_link">
    <inertial>
      <origin rpy="0 0 0" xyz="0.00115944166678269 0.00579999927481416 0.0107764194581964"/>
      <mass value="0.00872849065417814"/>
      <inertia ixx="1.50886455139492E-06" ixy="-1.78552622842378E-14" ixz="-2.60234059895028E-07" iyy="1.45214737233688E-06" iyz="-9.3509454025756E-14" izz="3.57695503495603E-07"/>
    </inertial>
    <visual>
      <origin rpy="0 0 0" xyz="0 0 0"/>
      <geometry>
        <mesh filename="package://ir_gazebo/urdf/rg2/meshes/visual/gripper_finger2_finger_tip_link.dae"/>
      </geometry>
      <material name="White">
        <color rgba="1 1 1 1"/>
      </material>
    </visual>
    <collision>
      <origin rpy="0 0 0" xyz="0 0 0"/>
      <geometry>
        <mesh filename="package://ir_gazebo/urdf/rg2/meshes/collision/gripper_finger2_finger_tip_link.STL"/>
      </geometry>
    </collision>
  </link>
  <joint name="gripper_finger2_finger_tip_joint" type="continuous">
    <origin rpy="0 0 0" xyz="-0.002 0.0042 0.054964"/>
    <parent link="gripper_finger2_inner_knuckle_link"/>
    <child link="gripper_finger2_finger_tip_link"/>
    <axis xyz="0 1 0"/>
    <limit effort="0.1" lower="-3.14" upper="3.14" velocity="100"/>
    <mimic joint="gripper_finger1_joint" offset="0"/>
  </joint>
</robot>
